============================= test session starts ==============================
platform linux -- Python 3.9.1, pytest-6.2.2, py-1.10.0, pluggy-0.13.1 -- /usr/local/bin/python
cachedir: .pytest_cache
Using --random-order-bucket=global
Using --random-order-seed=277884

rootdir: /sandbox
plugins: cov-2.11.1, mock-3.5.1, random-order-1.0.4
collecting ... collected 5 items

test_fizz_buzz.py::test_one_item PASSED                                  [ 20%]
test_fizz_buzz.py::test_first_multiple_of_3_and_5 FAILED                 [ 40%]
test_fizz_buzz.py::test_first_multiple_of_5 PASSED                       [ 60%]
test_fizz_buzz.py::test_first_multiple_of_3 PASSED                       [ 80%]
test_fizz_buzz.py::test_empty_list PASSED                                [100%]

=================================== FAILURES ===================================
________________________ test_first_multiple_of_3_and_5 ________________________

    def test_first_multiple_of_3_and_5():
>       assert fizz_buzz(5) == [1, 2, 'Fizz', 4, 'Buzz', 'Fizz', 7, 8, 'Fizz', 'Buzz', 11, 'Fizz', 13, 14, 'FizzBuzz']
E       AssertionError: assert [1, 2, 'Fizz', 4, 'Buzz'] == [1, 2, 'Fizz'..., 'Fizz', ...]
E         Right contains 10 more items, first extra item: 'Fizz'
E         Full diff:
E           [
E            1,
E            2,
E            'Fizz',
E            4,...
E         
E         ...Full output truncated (13 lines hidden), use '-vv' to show

test_fizz_buzz.py:16: AssertionError
=========================== short test summary info ============================
FAILED test_fizz_buzz.py::test_first_multiple_of_3_and_5 - AssertionError: as...
========================= 1 failed, 4 passed in 0.07s ==========================
